Workbook

Sheet Cover & Assumptions
B2: Diageo plc (LSE: DGE / NYSE: DEO)
B3: Discounted Cash Flow, Trading Comparables & Precedent Transaction Analysis
B4: Prepared for placement application preparation — illustrative valuation model | Valuation date: 11 September 2026
B6: COMPANY SNAPSHOT
B7: Share price (DEO, 11-Sep-2026) | C7: 86.41 | G7: Yahoo Finance, DEO quote, 11 Sep 2026
B8: Diluted shares outstanding (mm) | C8: 555.9 | G8: Morningstar / stockanalysis.com, Sep 2026
B9: Market capitalisation ($mm) | C9: =C7*C8 -> 48035.319 | G9: Share price x shares outstanding
B10: Net debt, FY2025A ($mm) | C10: 21854 | G10: Diageo FY25 Preliminary Results, 5-Aug-2025, p.17
B11: Enterprise value, current ($mm) | C11: =C9+C10 -> 69889.319 | G11: Market cap + net debt (cross-check: reported EV ~$71.1bn per stockanalysis.com)
B12: Fiscal year end | C12: 30-Jun | G12: Diageo FY runs 1 Jul - 30 Jun
B14: FY2025A KEY FINANCIALS ($mm, unless noted)
B15: Net sales | C15: 20245 | G15: Diageo FY25 Prelim Results, 5-Aug-2025
B16: Operating profit before exceptional items | C16: 5704 | G16: Diageo FY25 Prelim Results (adjusted operating profit)
B17: Operating margin before exceptional items | C17: =C16/C15 -> 0.28174858 | G17: EBIT before exceptionals / net sales
B18: D&A (excl. exceptional impairment) | C18: 748 | G18: Diageo FY25 Financial Report 2025, segmental note
B19: Net capital expenditure | C19: 1549 | G19: Diageo FY25 Prelim Results, p.17
B20: Net increase in working capital (cash outflow) | C20: 77 | G20: Diageo FY25 Financial Report, cash flow statement
B21: Effective tax rate FY25A | C21: =999/3537 -> 0.28244275 | G21: Taxation $999mm / profit before tax $3,537mm, FY25 Financial Report
B23: MODEL NAVIGATION
B24: • WACC — cost of capital build-up (CAPM)
B25: • DCF Model — 5-year unlevered FCF projection, terminal value, sensitivity
B26: • Trading Comps — listed spirits peer multiples applied to Diageo
B27: • Precedent Transactions — historical M&A multiples in beverage alcohol
B28: • Football Field — summary valuation range across all three methods
B30: KEY ASSUMPTIONS / NOTES
B31: - All figures in USD millions unless stated, matching Diageo's reported functional currency.
B32: - Base year FY2025A (year ended 30 June 2025). Explicit forecast FY2026E-FY2030E.
B33: - Blue cells = hardcoded inputs/sources. Black = formulas. Green = links to another sheet.
B34: - This is a self-directed, illustrative student model built from public filings for CV/interview preparation — not investment advice.

Sheet WACC
B2: Weighted Average Cost of Capital — CAPM Build-Up
B4: COST OF EQUITY (CAPM)
B5: Risk-free rate (US 10-year Treasury) | C5: 0.0495 | E5: U.S. 10Y Treasury yield, 11 Sep 2026 (FRED DGS10 / Bloomberg)
B6: Levered beta (5Y monthly, blended) | C6: 0.6 | E6: Providers show wide dispersion (Yahoo Finance 0.32, WallStreetZen 0.56-0.57); 0.60 used, at the upper end of the range, consistent with the independent WACC cross-check below
B7: Equity risk premium (US, long-run) | C7: 0.055 | E7: Standard long-run US ERP assumption (~5.5%), consistent with Damodaran-style estimates
B8: Cost of equity | C8: =C5+C6*C7 -> 0.0825 | E8: Rf + Beta x ERP
B10: COST OF DEBT
B11: Pre-tax cost of debt | C11: 0.055 | E11: Approx. Diageo blended cost of debt, 5-6% range (Simply Wall St / showmethevalue.substack.com FY25 analysis)
B12: Marginal tax rate | C12: 0.25 | E12: UK statutory corporation tax rate (2026), close to Diageo's FY25 effective rate of ~28%
B13: After-tax cost of debt | C13: =C11*(1-C12) -> 0.04125 | E13: Pre-tax cost of debt x (1 - tax rate)
B15: CAPITAL STRUCTURE WEIGHTS
B16: Market value of equity ($mm) | C16: ='Cover & Assumptions'!C9 -> 48035.319 | E16: Cover tab — current market capitalisation
B17: Net debt ($mm) | C17: ='Cover & Assumptions'!C10 -> 21854 | E17: Cover tab — FY25A net debt
B18: Total capital ($mm) | C18: =C16+C17 -> 69889.319 | E18: Equity + net debt
B19: Weight of equity (E/V) | C19: =C16/C18 -> 0.68730558 | E19: =
B20: Weight of debt (D/V) | C20: =C17/C18 -> 0.31269442 | E20: =
B22: WACC
B23: Weighted Average Cost of Capital | C23: =C19*C8+C20*C13 -> 0.069601355 | E23: (E/V x Cost of equity) + (D/V x After-tax cost of debt)
B25: Cross-check: showmethevalue.substack.com FY2025 analysis independently estimates Diageo's WACC at 7-8%, consistent with the build-up above.

Sheet DCF Model
B2: Diageo plc — Unlevered Free Cash Flow DCF (FY2026E-FY2030E)
B4: $ millions | C4: FY2025A | D4: FY2026E | E4: FY2027E | F4: FY2028E | G4: FY2029E | H4: FY2030E
B6: Net sales | C6: ='Cover & Assumptions'!C15 -> 20245 | D6: =C6*(1+D7) -> 20447.45 | E6: =D6*(1+E7) -> 20815.504 | F6: =E6*(1+F7) -> 21335.892 | G6: =F6*(1+G7) -> 21975.968 | H6: =G6*(1+H7) -> 22679.199
B7: % growth (organic, ex-FX/disposals) | D7: 0.01 | E7: 0.018 | F7: 0.025 | G7: 0.03 | H7: 0.032 | J7: Assumption: gradual recovery from FY25 tariff/volume headwinds toward ~3% mid-cycle organic growth by FY30, consistent with peer growth outlook (dealascent.com Q2 2026 beverages report; Diageo Accelerate targets).
B9: EBIT margin (before exceptional items) | C9: ='Cover & Assumptions'!C17 -> 0.28174858 | D9: 0.283 | E9: 0.287 | F9: 0.291 | G9: 0.295 | H9: 0.298 | J9: Assumption: gradual margin recovery toward ~30% as Accelerate cost programme and lower capex intensity offset tariff drag (Diageo FY25 Prelim Results, Accelerate programme commentary).
B10: EBIT | C10: =C6*C9 -> 5704 | D10: =D6*D9 -> 5786.6283 | E10: =E6*E9 -> 5974.0497 | F10: =F6*F9 -> 6208.7445 | G10: =G6*G9 -> 6482.9107 | H10: =H6*H9 -> 6758.4014
B12: Tax rate | C12: 0.25 | D12: =$C$12 -> 0.25 | E12: =$C$12 -> 0.25 | F12: =$C$12 -> 0.25 | G12: =$C$12 -> 0.25 | H12: =$C$12 -> 0.25 | J12: UK statutory corporation tax rate, held flat across the forecast (Cover tab notes FY25A effective rate ~28%).
B13: Less: taxes on EBIT | C13: =-C10*C12 -> -1426 | D13: =-D10*D12 -> -1446.6571 | E13: =-E10*E12 -> -1493.5124 | F13: =-F10*F12 -> -1552.1861 | G13: =-G10*G12 -> -1620.7277 | H13: =-H10*H12 -> -1689.6004
B14: NOPAT | C14: =C10+C13 -> 4278 | D14: =D10+D13 -> 4339.9713 | E14: =E10+E13 -> 4480.5373 | F14: =F10+F13 -> 4656.5584 | G14: =G10+G13 -> 4862.183 | H14: =H10+H13 -> 5068.8011
B16: D&A (% of net sales) | C16: =748/20245 -> 0.036947394 | D16: 0.036 | E16: 0.036 | F16: 0.035 | G16: 0.035 | H16: 0.035 | J16: FY25A D&A (excl. exceptional impairment) of $748mm = 3.7% of sales; held broadly flat (Diageo FY25 Financial Report).
B17: Add: D&A | C17: =C6*C16 -> 748 | D17: =D6*D16 -> 736.1082 | E17: =E6*E16 -> 749.35815 | F17: =F6*F16 -> 746.75621 | G17: =G6*G16 -> 769.1589 | H17: =H6*H16 -> 793.77198
B19: Capex (% of net sales) | C19: =1549/20245 -> 0.076512719 | D19: 0.07 | E19: 0.065 | F19: 0.06 | G19: 0.057 | H19: 0.055 | J19: FY25A net capex was 7.6% of sales; Diageo's Accelerate programme explicitly targets capex down to 'mid-single-digit' % of sales within 3 years (showmethevalue.substack.com FY2025 analysis; Diageo FY25 Prelim Results).
B20: Less: capital expenditure | C20: =-C6*C19 -> -1549 | D20: =-D6*D19 -> -1431.3215 | E20: =-E6*E19 -> -1353.0078 | F20: =-F6*F19 -> -1280.1535 | G20: =-G6*G19 -> -1252.6302 | H20: =-H6*H19 -> -1247.356
B22: Increase in net working capital (% of sales) | C22: =77/20245 -> 0.0038034082 | D22: 0.005 | E22: 0.005 | F22: 0.005 | G22: 0.004 | H22: 0.004 | J22: FY25A net working capital outflow was $77mm (0.4% of sales); assumed to stay small and roughly proportional to sales growth.
B23: Less: increase in net working capital | C23: =-C6*C22 -> -77 | D23: =-D6*D22 -> -102.23725 | E23: =-E6*E22 -> -104.07752 | F23: =-F6*F22 -> -106.67946 | G23: =-G6*G22 -> -87.903874 | H23: =-H6*H22 -> -90.716798
B25: Unlevered free cash flow | D25: =D14+D17+D20+D23 -> 3542.5207 | E25: =E14+E17+E20+E23 -> 3772.8101 | F25: =F14+F17+F20+F23 -> 4016.4816 | G25: =G14+G17+G20+G23 -> 4290.8078 | H25: =H14+H17+H20+H23 -> 4524.5003
B27: Discount period (mid-year convention not applied) | D27: 1 | E27: 2 | F27: 3 | G27: 4 | H27: 5
B28: Discount factor | D28: =1/(1+WACC!C23)^D27 -> 0.93492776 | E28: =1/(1+WACC!C23)^E27 -> 0.87408992 | F28: =1/(1+WACC!C23)^F27 -> 0.81721093 | G28: =1/(1+WACC!C23)^G27 -> 0.76403318 | H28: =1/(1+WACC!C23)^H27 -> 0.71431583
B29: PV of unlevered FCF | D29: =D25*D28 -> 3312.001 | E29: =E25*E28 -> 3297.7753 | F29: =F25*F28 -> 3282.3127 | G29: =G25*G28 -> 3278.3196 | H29: =H25*H28 -> 3231.9222
B31: TERMINAL VALUE — GORDON GROWTH METHOD
B32: Terminal growth rate (g) | C32: 0.02 | J32: Long-run assumption ~ global nominal GDP/inflation for a mature spirits business.
B33: WACC | C33: =WACC!C23 -> 0.069601355
B34: Terminal value at end of FY2030E | C34: =H25*(1+C32)/(C33-C32) -> 93041.617
B35: PV of terminal value | C35: =C34*H28 -> 66461.1
B37: ENTERPRISE & EQUITY VALUE BRIDGE (Gordon Growth basis)
B38: Sum of PV of explicit FCF (FY26E-FY30E) | C38: =SUM(D29:H29) -> 16402.331
B39: PV of terminal value | C39: =C35 -> 66461.1
B40: Implied enterprise value | C40: =C38+C39 -> 82863.431 | E40: TV as % of EV: | F40: =C39/C40 -> 0.80205586
B41: Less: net debt | C41: ='Cover & Assumptions'!C10 -> 21854
B42: Implied equity value | C42: =C40-C41 -> 61009.431
B43: Diluted shares outstanding (mm) | C43: ='Cover & Assumptions'!C8 -> 555.9
B44: Implied value per share | C44: =C42/C43 -> 109.74893
B45: Current share price (DEO) | C45: ='Cover & Assumptions'!C7 -> 86.41
B46: Implied upside / (downside) | C46: =C44/C45-1 -> 0.27009526
B48: CROSS-CHECK — EXIT MULTIPLE METHOD
B49: Exit EV/EBITDA multiple | C49: 11 | J49: Set at the median FY2026E EV/EBITDA of the trading comp set — see 'Trading Comps' tab.
B50: Terminal year EBITDA (FY2030E EBIT + D&A) | C50: =H10+H17 -> 7552.1734
B51: Terminal value (exit multiple) | C51: =C49*C50 -> 83073.908
B52: PV of terminal value (exit multiple) | C52: =C51*H28 -> 59341.008
B53: Implied enterprise value (exit multiple) | C53: =C38+C52 -> 75743.338
...

Sheet Trading Comps
B2: Trading Comparables — Listed Beverage Alcohol Peers
B3: Source: dealascent.com, 'Beverages M&A Q2 2026: Soft Drinks vs Alcohol Valuation' (EV/EBITDA 2026E, EBITDA margin); market caps as of Q2 2026 in local currency
B5: Company | C5: Country | D5: Mkt Cap (local ccy, mm) | E5: EV/EBITDA 2026E | F5: EBITDA Margin 2026E | G5: Rev Growth avg FY26-28E
B6: Rémy Cointreau SA | C6: France | D6: 2237 | E6: 13.8 | F6: 0.226 | G6: 0.012
B7: Constellation Brands | C7: US | D7: 31714 | E7: 11.2 | F7: 0.368 | G7: -0.03
B8: Davide Campari-Milano N.V. | C8: Netherlands | D8: 6649 | E8: 10.9 | F8: 0.25 | G8: 0.032
B9: Pernod Ricard | C9: France | D9: 15629 | E9: 9 | F9: 0.301 | G9: -0.035
B10: Diageo PLC (for reference — excluded from peer stats) | D10: 55656 | E10: 10.1 | F10: 0.325 | G10: -0.004
B12: PEER SET STATISTICS (excl. Diageo)
B13: Mean EV/EBITDA 2026E | E13: =AVERAGE(E6:E9) -> 11.225
B14: Median EV/EBITDA 2026E | E14: =MEDIAN(E6:E9) -> 11.05
B15: Low | E15: =MIN(E6:E9) -> 9
B16: High | E16: =MAX(E6:E9) -> 13.8
B18: IMPLIED VALUATION OF DIAGEO (applying peer multiples to Diageo FY25A EBITDA)
B19: Diageo FY2025A EBITDA (EBIT before exceptionals + D&A) | D19: 6452 | I19: $5,704mm EBIT before exceptional items + $748mm D&A (both per Cover & Assumptions tab, FY25A).
B21: Basis | C21: Multiple | D21: Implied EV ($mm) | E21: Implied share price
B22: Low (min peer multiple) | C22: =E15 -> 9 | D22: =C22*D19 -> 58068 | E22: =(D22-'Cover & Assumptions'!$C$10)/'Cover & Assumptions'!$C$8 -> 65.14481
B23: Median peer multiple | C23: =E14 -> 11.05 | D23: =C23*D19 -> 71294.6 | E23: =(D23-'Cover & Assumptions'!$C$10)/'Cover & Assumptions'!$C$8 -> 88.937938
B24: Mean peer multiple | C24: =E13 -> 11.225 | D24: =C24*D19 -> 72423.7 | E24: =(D24-'Cover & Assumptions'!$C$10)/'Cover & Assumptions'!$C$8 -> 90.969059
B25: High (max peer multiple) | C25: =E16 -> 13.8 | D25: =C25*D19 -> 89037.6 | E25: =(D25-'Cover & Assumptions'!$C$10)/'Cover & Assumptions'!$C$8 -> 120.85555
B27: Cross-check: applying the peer median (~11.1x) to Diageo's FY25A EBITDA of ~$6.45bn implies an EV of ~$71-72bn, closely matching Diageo's actual current EV (~$71bn) — a reasonable sanity check on both the peer set and Diageo's own EBITDA base.

Sheet Precedent Transactions
B2: Precedent Transaction Analysis — Beverage Alcohol M&A
B3: Selected historical deals in spirits/beverage alcohol with disclosed enterprise value and multiple data
B5: Date | C5: Target | D5: Acquirer | E5: Subsector | F5: Deal EV ($mm) | G5: EV/EBITDA | H5: Source
B6: Jan-2014 | C6: Beam Inc. | D6: Suntory Holdings | E6: Spirits (bourbon/global) | F6: 16000 | G6: 20 | H6: just-drinks.com, 'Spirits Acquisition Multiples 2001-Present' (Nomura data)
B7: Dec-2025 | C7: East African Breweries (EABL) | D7: Asahi Group Holdings | E7: Beer & spirits (East Africa) | F7: 3807 | G7: 15.3 | H7: dealascent.com, Beverages M&A Q2 2026 report
B8: May-2026 | C8: Averna & Zedda Piras | D8: Illva Saronno | E8: Spirits (Italian amari/liqueurs) | F8: 108 | G8: 8.3 | H8: dealascent.com, Beverages M&A Q2 2026 report (EUR100mm converted at ~1.08 EUR/USD)
B9: Jan-2019 | C9: Fuller, Smith & Turner (beer business) | D9: Asahi Group Holdings | E9: Beer (UK) | F9: n/d | G9: 23.6 | H9: Craft Brew Alliance DEFM14A (2020), Goldman Sachs selected transactions analysis
B11: Note: EV/Revenue-only deals (e.g. AB InBev/BeatBox Beverages, Dec-2025, 2.6x EV/Revenue; Diageo/Lobos 1707-Cîroc swap, 2025) are excluded here as they lack disclosed EBITDA multiples comparable to the set above (Capstone Partners Beverage M&A Coverage Report, March 2026; Park Street 'Roundup of M&A in 2025').
B13: PRECEDENT TRANSACTION STATISTICS (EV/EBITDA)
B14: (Statistics below computed on the three spirits-only deals; the Fuller/Asahi UK beer deal is shown for reference but excluded as an outlier from a different subsector.)
B15: Mean (spirits deals only) | F15: =AVERAGE(G6,G7,G8) -> 14.533333
B16: Median (spirits deals only) | F16: =MEDIAN(G6,G7,G8) -> 15.3
B17: Low (spirits deals only) | F17: =MIN(G6,G7,G8) -> 8.3
B18: High (spirits deals only) | F18: =MAX(G6,G7,G8) -> 20
B20: Precedent multiples embed a control premium and are systematically higher than trading comps (e.g. Beam/Suntory at 20x reflected a strategic, scarcity-value premium for a scaled American whiskey platform). Applying these multiples to a minority-stake DCF/comps context would overstate value; they are shown here as a cross-check on M&A-implied pricing rather than a primary valuation basis for Diageo.
B23: IMPLIED VALUATION OF DIAGEO (illustrative — applying precedent multiples to FY25A EBITDA)
B24: Diageo FY2025A EBITDA | F24: 6452
B26: Basis | C26: Multiple | D26: Implied EV ($mm) | E26: Implied share price
B27: Low | C27: =F17 -> 8.3 | D27: =C27*F24 -> 53551.6 | E27: =(D27-'Cover & Assumptions'!$C$10)/'Cover & Assumptions'!$C$8 -> 57.020327
B28: Median | C28: =F16 -> 15.3 | D28: =C28*F24 -> 98715.6 | E28: =(D28-'Cover & Assumptions'!$C$10)/'Cover & Assumptions'!$C$8 -> 138.26516
B29: High | C29: =F18 -> 20 | D29: =C29*F24 -> 129040 | E29: =(D29-'Cover & Assumptions'!$C$10)/'Cover & Assumptions'!$C$8 -> 192.81525

Sheet Football Field
B2: Diageo plc — Valuation Summary ('Football Field')
B3: Implied value per share ($) across methodologies
B5: Methodology | C5: Low | D5: High | E5: Base / Median
B6: DCF — Gordon Growth (sensitivity range) | C6: =MIN('DCF Model'!C59:G63) -> 69.916664 | D6: =MAX('DCF Model'!C59:G63) -> 203.06091 | E6: ='DCF Model'!C44 -> 109.74893
B7: Trading Comps (EV/EBITDA) | C7: ='Trading Comps'!E22 -> 65.14481 | D7: ='Trading Comps'!E25 -> 120.85555 | E7: ='Trading Comps'!E23 -> 88.937938
B8: Precedent Transactions (EV/EBITDA) | C8: ='Precedent Transactions'!E27 -> 57.020327 | D8: ='Precedent Transactions'!E29 -> 192.81525 | E8: ='Precedent Transactions'!E28 -> 138.26516
B10: Current share price (DEO) | E10: ='Cover & Assumptions'!C7 -> 86.41
B12: Trading comps and the DCF centre case bracket the current share price closely, suggesting the market is pricing Diageo close to fair value on a fundamentals basis. Precedent transaction multiples sit meaningfully higher, reflecting the control premium a strategic acquirer would pay (as seen in the March 2026 Pernod Ricard / Brown-Forman merger talks) rather than a standalone public-market valuation.
B15: CHART DATA (base = low value, range = high-low, used to build a floating bar chart)
B16: Methodology | C16: Base (Low) | D16: Range (High-Low)
B17: =B6 -> DCF — Gordon Growth (sensitivity range) | C17: =C6 -> 69.916664 | D17: =D6-C6 -> 133.14425
B18: =B7 -> Trading Comps (EV/EBITDA) | C18: =C7 -> 65.14481 | D18: =D7-C7 -> 55.710739
B19: =B8 -> Precedent Transactions (EV/EBITDA) | C19: =C8 -> 57.020327 | D19: =D8-C8 -> 135.79493
